#VRML_SIM R2020a utf8
WorldInfo {
}
Viewpoint {
  orientation -0.052330350923618436 0.9723794133919152 0.22746386698507928 2.674570879399217
  position 1.2969243036770122 1.4030722948542365 -2.327904463106398
  follow "robot:inf_right"
}
TexturedBackground {
}
TexturedBackgroundLight {
}
Robot {
  translation -0.0539127 0.0485212 0.229573
  rotation 0.0018680552589844 0.9999963882139613 0.0019323375952818218 -1.5721038512920498
  children [
    DEF BODY Shape {
      appearance PBRAppearance {
        baseColor 1 0 0
        roughness 1
        metalness 0
      }
      geometry Box {
        size 0.1 0.05 0.2
      }
    }
    HingeJoint {
      jointParameters HingeJointParameters {
        position 2768.9508427964515
        anchor 0.06 0 0.05
      }
      device [
        RotationalMotor {
          name "wheel1"
        }
      ]
      endPoint DEF WHEEL1 Solid {
        translation 0.06 0 0.05
        rotation 0.6355319259111518 -0.6355342603545204 -0.4384009295876265 3.9679227150160203
        children [
          DEF WHEEL Shape {
            appearance PBRAppearance {
              baseColor 0 1 0
              roughness 1
              metalness 0
            }
            geometry Cylinder {
              height 0.02
              radius 0.04
            }
          }
        ]
        boundingObject USE WHEEL
        physics DEF WHEEL_PH Physics {
        }
      }
    }
    HingeJoint {
      jointParameters HingeJointParameters {
        position 2323.5518724354147
        anchor 0.06 0 -0.05
      }
      device [
        RotationalMotor {
          name "wheel3"
        }
      ]
      endPoint DEF WHEEL3 Solid {
        translation 0.06 0 -0.05
        rotation -0.49886471088273715 0.49886654331848135 0.7087073953285324 1.9085041596820589
        children [
          USE WHEEL
        ]
        name "solid(1)"
        boundingObject USE WHEEL
        physics USE WHEEL_PH
      }
    }
    HingeJoint {
      jointParameters HingeJointParameters {
        position 2402.11526781694
        anchor -0.06 0 -0.05
      }
      device [
        RotationalMotor {
          name "wheel4"
        }
      ]
      endPoint DEF WHEEL4 Solid {
        translation -0.06 0 -0.05
        rotation 0.6361317701523701 -0.6361341067990992 0.4366574964084829 2.3181892031248217
        children [
          USE WHEEL
        ]
        name "solid(2)"
        boundingObject USE WHEEL
        physics USE WHEEL_PH
      }
    }
    HingeJoint {
      jointParameters HingeJointParameters {
        position 1956.0244093876533
        anchor -0.06 0 0.05
      }
      device [
        RotationalMotor {
          name "wheel2"
        }
      ]
      endPoint DEF WHEEL2 Solid {
        translation -0.06 0 0.05
        rotation -0.6381028774613375 0.6381052213483658 -0.43086708421915254 3.9552491966657177
        children [
          USE WHEEL
        ]
        name "solid(3)"
        boundingObject USE WHEEL
        physics USE WHEEL_PH
      }
    }
    DistanceSensor {
      translation 0.025 0 0.1
      rotation 0 1 0 -1
      children [
        Shape {
          appearance PBRAppearance {
            baseColor 0 0 1
            roughness 1
            metalness 0
          }
          geometry Box {
            size 0.01 0.01 0.01
          }
        }
      ]
      name "ds_left"
    }
    DistanceSensor {
      translation -0.025 0 0.1
      rotation 0 1 0 -2
      children [
        Shape {
          appearance PBRAppearance {
            baseColor 0 0 1
            roughness 1
            metalness 0
          }
          geometry Box {
            size 0.01 0.01 0.01
          }
        }
      ]
      name "ds_right"
    }
    DistanceSensor {
      translation -0.015 -0.02 0.1
      rotation 0.5773502691896258 -0.5773502691896258 -0.5773502691896258 2
      children [
        Shape {
          appearance PBRAppearance {
          }
          geometry Box {
            size 0.01 0.01 0.01
          }
        }
      ]
      name "inf_right"
      type "infra-red"
    }
    DistanceSensor {
      translation 0 -0.02 0.1
      rotation 0.5773502691896258 -0.5773502691896258 -0.5773502691896258 2
      children [
        Shape {
          appearance PBRAppearance {
          }
          geometry Box {
            size 0.01 0.01 0.01
          }
        }
      ]
      name "inf_cent"
      type "infra-red"
    }
    DistanceSensor {
      translation 0.015 -0.02 0.1
      rotation 0.5773502691896258 -0.5773502691896258 -0.5773502691896258 2
      children [
        Shape {
          appearance PBRAppearance {
          }
          geometry Box {
            size 0.01 0.01 0.01
          }
        }
      ]
      name "inf_left"
      type "infra-red"
    }
    LightSensor {
      translation 0 0 0.1
      children [
        Shape {
          appearance PBRAppearance {
            baseColor 1 1 0
          }
          geometry Box {
            size 0.01 0.01 0.01
          }
        }
      ]
      name "light"
    }
    Camera {
      translation 0 0.02 0.1
      rotation 0 1 0 3.14159
      children [
        Transform {
          children [
            Shape {
              appearance PBRAppearance {
                roughness 1
                metalness 0
              }
              geometry Box {
                size 0.01 0.01 0.01
              }
            }
          ]
        }
      ]
      fieldOfView 0.9
      width 256
      height 128
      antiAliasing TRUE
      recognition Recognition {
        frameColor 1 1 0.498039
      }
    }
  ]
  boundingObject USE BODY
  physics Physics {
  }
  controller "controller"
}
DEF floor Solid {
  translation -0.37 0 0.25
  children [
    Shape {
      appearance PBRAppearance {
        roughness 1
        metalness 0
      }
      geometry Box {
        size 10 0.01 10
      }
    }
  ]
  name "floor"
  boundingObject Box {
    size 10 0.01 10
  }
}
